package com.kcaluru.burlapbot.worldgen;

import java.util.Random;

import net.minecraft.block.Block;
import net.minecraft.init.Blocks;
import net.minecraft.world.World;
import net.minecraft.world.chunk.IChunkProvider;
import net.minecraft.world.gen.feature.WorldGenerator;
import cpw.mods.fml.common.IWorldGenerator;

public class WorldGenBurlapDungeon extends WorldGenerator implements IWorldGenerator
{
	public WorldGenBurlapDungeon() { }

	@Override
	public void generate(Random random, int chunkX, int chunkZ, World world, IChunkProvider chunkGenerator, IChunkProvider chunkProvider) { }

	public void setBlock(World world, int x, int y, int z, Block block, int metadata)
	{
		Block b1 = world.getBlock(x, y, z);

		if(b1.isAir(world, x, y, z) || b1.isLeaves(world, x, y, z))
		{
			world.setBlock(x, y, z, block, metadata, 2);
		}
	}

	public boolean generate(World world, Random rand, int i, int j, int k) {
		this.setBlock(world, i + 0, j + 0, k + 0, Blocks.bedrock, 0);
		this.setBlock(world, i + 0, j + 0, k + 1, Blocks.bedrock, 0);
		this.setBlock(world, i + 0, j + 0, k + 2, Blocks.bedrock, 0);
		this.setBlock(world, i + 0, j + 0, k + 3, Blocks.bedrock, 0);
		this.setBlock(world, i + 0, j + 0, k + 4, Blocks.bedrock, 0);
		this.setBlock(world, i + 0, j + 0, k + 5, Blocks.bedrock, 0);
		this.setBlock(world, i + 0, j + 0, k + 6, Blocks.bedrock, 0);
		this.setBlock(world, i + 0, j + 0, k + 7, Blocks.bedrock, 0);
		this.setBlock(world, i + 0, j + 0, k + 8, Blocks.bedrock, 0);
		this.setBlock(world, i + 0, j + 0, k + 9, Blocks.bedrock, 0);
		this.setBlock(world, i + 0, j + 0, k + 10, Blocks.bedrock, 0);
		this.setBlock(world, i + 0, j + 1, k + 0, Blocks.bedrock, 0);
		this.setBlock(world, i + 0, j + 1, k + 1, Blocks.bedrock, 0);
		this.setBlock(world, i + 0, j + 1, k + 2, Blocks.bedrock, 0);
		this.setBlock(world, i + 0, j + 1, k + 3, Blocks.bedrock, 0);
		this.setBlock(world, i + 0, j + 1, k + 4, Blocks.bedrock, 0);
		this.setBlock(world, i + 0, j + 1, k + 5, Blocks.bedrock, 0);
		this.setBlock(world, i + 0, j + 1, k + 6, Blocks.bedrock, 0);
		this.setBlock(world, i + 0, j + 1, k + 7, Blocks.bedrock, 0);
		this.setBlock(world, i + 0, j + 1, k + 8, Blocks.bedrock, 0);
		this.setBlock(world, i + 0, j + 1, k + 9, Blocks.bedrock, 0);
		this.setBlock(world, i + 0, j + 1, k + 10, Blocks.bedrock, 0);
		this.setBlock(world, i + 0, j + 2, k + 0, Blocks.bedrock, 0);
		this.setBlock(world, i + 0, j + 2, k + 1, Blocks.bedrock, 0);
		this.setBlock(world, i + 0, j + 2, k + 2, Blocks.bedrock, 0);
		this.setBlock(world, i + 0, j + 2, k + 3, Blocks.bedrock, 0);
		this.setBlock(world, i + 0, j + 2, k + 4, Blocks.bedrock, 0);
		this.setBlock(world, i + 0, j + 2, k + 5, Blocks.bedrock, 0);
		this.setBlock(world, i + 0, j + 2, k + 6, Blocks.bedrock, 0);
		this.setBlock(world, i + 0, j + 2, k + 7, Blocks.bedrock, 0);
		this.setBlock(world, i + 0, j + 2, k + 8, Blocks.bedrock, 0);
		this.setBlock(world, i + 0, j + 2, k + 9, Blocks.bedrock, 0);
		this.setBlock(world, i + 0, j + 2, k + 10, Blocks.bedrock, 0);
		this.setBlock(world, i + 0, j + 3, k + 0, Blocks.bedrock, 0);
		this.setBlock(world, i + 0, j + 3, k + 1, Blocks.bedrock, 0);
		this.setBlock(world, i + 0, j + 3, k + 2, Blocks.bedrock, 0);
		this.setBlock(world, i + 0, j + 3, k + 3, Blocks.bedrock, 0);
		this.setBlock(world, i + 0, j + 3, k + 4, Blocks.bedrock, 0);
		this.setBlock(world, i + 0, j + 3, k + 5, Blocks.bedrock, 0);
		this.setBlock(world, i + 0, j + 3, k + 6, Blocks.bedrock, 0);
		this.setBlock(world, i + 0, j + 3, k + 7, Blocks.bedrock, 0);
		this.setBlock(world, i + 0, j + 3, k + 8, Blocks.bedrock, 0);
		this.setBlock(world, i + 0, j + 3, k + 9, Blocks.bedrock, 0);
		this.setBlock(world, i + 0, j + 3, k + 10, Blocks.bedrock, 0);
		this.setBlock(world, i + 0, j + 4, k + 0, Blocks.bedrock, 0);
		this.setBlock(world, i + 0, j + 4, k + 1, Blocks.bedrock, 0);
		this.setBlock(world, i + 0, j + 4, k + 2, Blocks.bedrock, 0);
		this.setBlock(world, i + 0, j + 4, k + 3, Blocks.bedrock, 0);
		this.setBlock(world, i + 0, j + 4, k + 4, Blocks.bedrock, 0);
		this.setBlock(world, i + 0, j + 4, k + 5, Blocks.bedrock, 0);
		this.setBlock(world, i + 0, j + 4, k + 6, Blocks.bedrock, 0);
		this.setBlock(world, i + 0, j + 4, k + 7, Blocks.bedrock, 0);
		this.setBlock(world, i + 0, j + 4, k + 8, Blocks.bedrock, 0);
		this.setBlock(world, i + 0, j + 4, k + 9, Blocks.bedrock, 0);
		this.setBlock(world, i + 0, j + 4, k + 10, Blocks.bedrock, 0);
		this.setBlock(world, i + 0, j + 5, k + 0, Blocks.bedrock, 0);
		this.setBlock(world, i + 0, j + 5, k + 1, Blocks.bedrock, 0);
		this.setBlock(world, i + 0, j + 5, k + 2, Blocks.bedrock, 0);
		this.setBlock(world, i + 0, j + 5, k + 3, Blocks.bedrock, 0);
		this.setBlock(world, i + 0, j + 5, k + 4, Blocks.bedrock, 0);
		this.setBlock(world, i + 0, j + 5, k + 5, Blocks.bedrock, 0);
		this.setBlock(world, i + 0, j + 5, k + 6, Blocks.bedrock, 0);
		this.setBlock(world, i + 0, j + 5, k + 7, Blocks.bedrock, 0);
		this.setBlock(world, i + 0, j + 5, k + 8, Blocks.bedrock, 0);
		this.setBlock(world, i + 0, j + 5, k + 9, Blocks.bedrock, 0);
		this.setBlock(world, i + 0, j + 5, k + 10, Blocks.bedrock, 0);
		this.setBlock(world, i + 0, j + 6, k + 0, Blocks.bedrock, 0);
		this.setBlock(world, i + 0, j + 6, k + 1, Blocks.bedrock, 0);
		this.setBlock(world, i + 0, j + 6, k + 2, Blocks.bedrock, 0);
		this.setBlock(world, i + 0, j + 6, k + 3, Blocks.bedrock, 0);
		this.setBlock(world, i + 0, j + 6, k + 4, Blocks.bedrock, 0);
		this.setBlock(world, i + 0, j + 6, k + 5, Blocks.bedrock, 0);
		this.setBlock(world, i + 0, j + 6, k + 6, Blocks.bedrock, 0);
		this.setBlock(world, i + 0, j + 6, k + 7, Blocks.bedrock, 0);
		this.setBlock(world, i + 0, j + 6, k + 8, Blocks.bedrock, 0);
		this.setBlock(world, i + 0, j + 6, k + 9, Blocks.bedrock, 0);
		this.setBlock(world, i + 0, j + 6, k + 10, Blocks.bedrock, 0);
		this.setBlock(world, i + 1, j + 0, k + 0, Blocks.bedrock, 0);
		this.setBlock(world, i + 1, j + 0, k + 1, Blocks.bedrock, 0);
		this.setBlock(world, i + 1, j + 0, k + 2, Blocks.bedrock, 0);
		this.setBlock(world, i + 1, j + 0, k + 3, Blocks.bedrock, 0);
		this.setBlock(world, i + 1, j + 0, k + 4, Blocks.bedrock, 0);
		this.setBlock(world, i + 1, j + 0, k + 5, Blocks.bedrock, 0);
		this.setBlock(world, i + 1, j + 0, k + 6, Blocks.bedrock, 0);
		this.setBlock(world, i + 1, j + 0, k + 7, Blocks.bedrock, 0);
		this.setBlock(world, i + 1, j + 0, k + 8, Blocks.bedrock, 0);
		this.setBlock(world, i + 1, j + 0, k + 9, Blocks.bedrock, 0);
		this.setBlock(world, i + 1, j + 0, k + 10, Blocks.bedrock, 0);
		this.setBlock(world, i + 1, j + 1, k + 0, Blocks.bedrock, 0);
		this.setBlock(world, i + 1, j + 1, k + 1, Blocks.air, 0);
		this.setBlock(world, i + 1, j + 1, k + 2, Blocks.air, 0);
		this.setBlock(world, i + 1, j + 1, k + 3, Blocks.air, 0);
		this.setBlock(world, i + 1, j + 1, k + 4, Blocks.air, 0);
		this.setBlock(world, i + 1, j + 1, k + 5, Blocks.air, 0);
		this.setBlock(world, i + 1, j + 1, k + 6, Blocks.dirt, 0);
		this.setBlock(world, i + 1, j + 1, k + 7, Blocks.air, 0);
		this.setBlock(world, i + 1, j + 1, k + 8, Blocks.air, 0);
		this.setBlock(world, i + 1, j + 1, k + 9, Blocks.glowstone, 0);
		this.setBlock(world, i + 1, j + 1, k + 10, Blocks.bedrock, 0);
		this.setBlock(world, i + 1, j + 2, k + 0, Blocks.bedrock, 0);
		this.setBlock(world, i + 1, j + 2, k + 1, Blocks.air, 0);
		this.setBlock(world, i + 1, j + 2, k + 2, Blocks.air, 0);
		this.setBlock(world, i + 1, j + 2, k + 3, Blocks.air, 0);
		this.setBlock(world, i + 1, j + 2, k + 4, Blocks.air, 0);
		this.setBlock(world, i + 1, j + 2, k + 5, Blocks.air, 0);
		this.setBlock(world, i + 1, j + 2, k + 6, Blocks.dirt, 0);
		this.setBlock(world, i + 1, j + 2, k + 7, Blocks.air, 0);
		this.setBlock(world, i + 1, j + 2, k + 8, Blocks.air, 0);
		this.setBlock(world, i + 1, j + 2, k + 9, Blocks.air, 0);
		this.setBlock(world, i + 1, j + 2, k + 10, Blocks.bedrock, 0);
		this.setBlock(world, i + 1, j + 3, k + 0, Blocks.bedrock, 0);
		this.setBlock(world, i + 1, j + 3, k + 1, Blocks.air, 0);
		this.setBlock(world, i + 1, j + 3, k + 2, Blocks.air, 0);
		this.setBlock(world, i + 1, j + 3, k + 3, Blocks.air, 0);
		this.setBlock(world, i + 1, j + 3, k + 4, Blocks.air, 0);
		this.setBlock(world, i + 1, j + 3, k + 5, Blocks.air, 0);
		this.setBlock(world, i + 1, j + 3, k + 6, Blocks.air, 0);
		this.setBlock(world, i + 1, j + 3, k + 7, Blocks.air, 0);
		this.setBlock(world, i + 1, j + 3, k + 8, Blocks.air, 0);
		this.setBlock(world, i + 1, j + 3, k + 9, Blocks.air, 0);
		this.setBlock(world, i + 1, j + 3, k + 10, Blocks.bedrock, 0);
		this.setBlock(world, i + 1, j + 4, k + 0, Blocks.bedrock, 0);
		this.setBlock(world, i + 1, j + 4, k + 1, Blocks.air, 0);
		this.setBlock(world, i + 1, j + 4, k + 2, Blocks.air, 0);
		this.setBlock(world, i + 1, j + 4, k + 3, Blocks.air, 0);
		this.setBlock(world, i + 1, j + 4, k + 4, Blocks.air, 0);
		this.setBlock(world, i + 1, j + 4, k + 5, Blocks.air, 0);
		this.setBlock(world, i + 1, j + 4, k + 6, Blocks.air, 0);
		this.setBlock(world, i + 1, j + 4, k + 7, Blocks.air, 0);
		this.setBlock(world, i + 1, j + 4, k + 8, Blocks.air, 0);
		this.setBlock(world, i + 1, j + 4, k + 9, Blocks.air, 0);
		this.setBlock(world, i + 1, j + 4, k + 10, Blocks.bedrock, 0);
		this.setBlock(world, i + 1, j + 5, k + 0, Blocks.bedrock, 0);
		this.setBlock(world, i + 1, j + 5, k + 1, Blocks.air, 0);
		this.setBlock(world, i + 1, j + 5, k + 2, Blocks.air, 0);
		this.setBlock(world, i + 1, j + 5, k + 3, Blocks.air, 0);
		this.setBlock(world, i + 1, j + 5, k + 4, Blocks.air, 0);
		this.setBlock(world, i + 1, j + 5, k + 5, Blocks.air, 0);
		this.setBlock(world, i + 1, j + 5, k + 6, Blocks.air, 0);
		this.setBlock(world, i + 1, j + 5, k + 7, Blocks.air, 0);
		this.setBlock(world, i + 1, j + 5, k + 8, Blocks.air, 0);
		this.setBlock(world, i + 1, j + 5, k + 9, Blocks.air, 0);
		this.setBlock(world, i + 1, j + 5, k + 10, Blocks.bedrock, 0);
		this.setBlock(world, i + 1, j + 6, k + 0, Blocks.bedrock, 0);
		this.setBlock(world, i + 1, j + 6, k + 1, Blocks.air, 0);
		this.setBlock(world, i + 1, j + 6, k + 2, Blocks.air, 0);
		this.setBlock(world, i + 1, j + 6, k + 3, Blocks.air, 0);
		this.setBlock(world, i + 1, j + 6, k + 4, Blocks.air, 0);
		this.setBlock(world, i + 1, j + 6, k + 5, Blocks.air, 0);
		this.setBlock(world, i + 1, j + 6, k + 6, Blocks.air, 0);
		this.setBlock(world, i + 1, j + 6, k + 7, Blocks.air, 0);
		this.setBlock(world, i + 1, j + 6, k + 8, Blocks.air, 0);
		this.setBlock(world, i + 1, j + 6, k + 9, Blocks.air, 0);
		this.setBlock(world, i + 1, j + 6, k + 10, Blocks.bedrock, 0);
		this.setBlock(world, i + 2, j + 0, k + 0, Blocks.bedrock, 0);
		this.setBlock(world, i + 2, j + 0, k + 1, Blocks.bedrock, 0);
		this.setBlock(world, i + 2, j + 0, k + 2, Blocks.bedrock, 0);
		this.setBlock(world, i + 2, j + 0, k + 3, Blocks.bedrock, 0);
		this.setBlock(world, i + 2, j + 0, k + 4, Blocks.bedrock, 0);
		this.setBlock(world, i + 2, j + 0, k + 5, Blocks.bedrock, 0);
		this.setBlock(world, i + 2, j + 0, k + 6, Blocks.bedrock, 0);
		this.setBlock(world, i + 2, j + 0, k + 7, Blocks.bedrock, 0);
		this.setBlock(world, i + 2, j + 0, k + 8, Blocks.bedrock, 0);
		this.setBlock(world, i + 2, j + 0, k + 9, Blocks.bedrock, 0);
		this.setBlock(world, i + 2, j + 0, k + 10, Blocks.bedrock, 0);
		this.setBlock(world, i + 2, j + 1, k + 0, Blocks.bedrock, 0);
		this.setBlock(world, i + 2, j + 1, k + 1, Blocks.dirt, 0);
		this.setBlock(world, i + 2, j + 1, k + 2, Blocks.air, 0);
		this.setBlock(world, i + 2, j + 1, k + 3, Blocks.air, 0);
		this.setBlock(world, i + 2, j + 1, k + 4, Blocks.air, 0);
		this.setBlock(world, i + 2, j + 1, k + 5, Blocks.air, 0);
		this.setBlock(world, i + 2, j + 1, k + 6, Blocks.dirt, 0);
		this.setBlock(world, i + 2, j + 1, k + 7, Blocks.air, 0);
		this.setBlock(world, i + 2, j + 1, k + 8, Blocks.air, 0);
		this.setBlock(world, i + 2, j + 1, k + 9, Blocks.air, 0);
		this.setBlock(world, i + 2, j + 1, k + 10, Blocks.bedrock, 0);
		this.setBlock(world, i + 2, j + 2, k + 0, Blocks.bedrock, 0);
		this.setBlock(world, i + 2, j + 2, k + 1, Blocks.air, 0);
		this.setBlock(world, i + 2, j + 2, k + 2, Blocks.air, 0);
		this.setBlock(world, i + 2, j + 2, k + 3, Blocks.air, 0);
		this.setBlock(world, i + 2, j + 2, k + 4, Blocks.air, 0);
		this.setBlock(world, i + 2, j + 2, k + 5, Blocks.air, 0);
		this.setBlock(world, i + 2, j + 2, k + 6, Blocks.air, 0);
		this.setBlock(world, i + 2, j + 2, k + 7, Blocks.air, 0);
		this.setBlock(world, i + 2, j + 2, k + 8, Blocks.air, 0);
		this.setBlock(world, i + 2, j + 2, k + 9, Blocks.air, 0);
		this.setBlock(world, i + 2, j + 2, k + 10, Blocks.bedrock, 0);
		this.setBlock(world, i + 2, j + 3, k + 0, Blocks.bedrock, 0);
		this.setBlock(world, i + 2, j + 3, k + 1, Blocks.air, 0);
		this.setBlock(world, i + 2, j + 3, k + 2, Blocks.air, 0);
		this.setBlock(world, i + 2, j + 3, k + 3, Blocks.air, 0);
		this.setBlock(world, i + 2, j + 3, k + 4, Blocks.air, 0);
		this.setBlock(world, i + 2, j + 3, k + 5, Blocks.air, 0);
		this.setBlock(world, i + 2, j + 3, k + 6, Blocks.air, 0);
		this.setBlock(world, i + 2, j + 3, k + 7, Blocks.air, 0);
		this.setBlock(world, i + 2, j + 3, k + 8, Blocks.air, 0);
		this.setBlock(world, i + 2, j + 3, k + 9, Blocks.air, 0);
		this.setBlock(world, i + 2, j + 3, k + 10, Blocks.bedrock, 0);
		this.setBlock(world, i + 2, j + 4, k + 0, Blocks.bedrock, 0);
		this.setBlock(world, i + 2, j + 4, k + 1, Blocks.air, 0);
		this.setBlock(world, i + 2, j + 4, k + 2, Blocks.air, 0);
		this.setBlock(world, i + 2, j + 4, k + 3, Blocks.air, 0);
		this.setBlock(world, i + 2, j + 4, k + 4, Blocks.air, 0);
		this.setBlock(world, i + 2, j + 4, k + 5, Blocks.air, 0);
		this.setBlock(world, i + 2, j + 4, k + 6, Blocks.air, 0);
		this.setBlock(world, i + 2, j + 4, k + 7, Blocks.air, 0);
		this.setBlock(world, i + 2, j + 4, k + 8, Blocks.air, 0);
		this.setBlock(world, i + 2, j + 4, k + 9, Blocks.air, 0);
		this.setBlock(world, i + 2, j + 4, k + 10, Blocks.bedrock, 0);
		this.setBlock(world, i + 2, j + 5, k + 0, Blocks.bedrock, 0);
		this.setBlock(world, i + 2, j + 5, k + 1, Blocks.air, 0);
		this.setBlock(world, i + 2, j + 5, k + 2, Blocks.air, 0);
		this.setBlock(world, i + 2, j + 5, k + 3, Blocks.air, 0);
		this.setBlock(world, i + 2, j + 5, k + 4, Blocks.air, 0);
		this.setBlock(world, i + 2, j + 5, k + 5, Blocks.air, 0);
		this.setBlock(world, i + 2, j + 5, k + 6, Blocks.air, 0);
		this.setBlock(world, i + 2, j + 5, k + 7, Blocks.air, 0);
		this.setBlock(world, i + 2, j + 5, k + 8, Blocks.air, 0);
		this.setBlock(world, i + 2, j + 5, k + 9, Blocks.air, 0);
		this.setBlock(world, i + 2, j + 5, k + 10, Blocks.bedrock, 0);
		this.setBlock(world, i + 2, j + 6, k + 0, Blocks.bedrock, 0);
		this.setBlock(world, i + 2, j + 6, k + 1, Blocks.air, 0);
		this.setBlock(world, i + 2, j + 6, k + 2, Blocks.air, 0);
		this.setBlock(world, i + 2, j + 6, k + 3, Blocks.air, 0);
		this.setBlock(world, i + 2, j + 6, k + 4, Blocks.air, 0);
		this.setBlock(world, i + 2, j + 6, k + 5, Blocks.air, 0);
		this.setBlock(world, i + 2, j + 6, k + 6, Blocks.air, 0);
		this.setBlock(world, i + 2, j + 6, k + 7, Blocks.air, 0);
		this.setBlock(world, i + 2, j + 6, k + 8, Blocks.air, 0);
		this.setBlock(world, i + 2, j + 6, k + 9, Blocks.air, 0);
		this.setBlock(world, i + 2, j + 6, k + 10, Blocks.bedrock, 0);
		this.setBlock(world, i + 3, j + 0, k + 0, Blocks.bedrock, 0);
		this.setBlock(world, i + 3, j + 0, k + 1, Blocks.bedrock, 0);
		this.setBlock(world, i + 3, j + 0, k + 2, Blocks.bedrock, 0);
		this.setBlock(world, i + 3, j + 0, k + 3, Blocks.bedrock, 0);
		this.setBlock(world, i + 3, j + 0, k + 4, Blocks.bedrock, 0);
		this.setBlock(world, i + 3, j + 0, k + 5, Blocks.bedrock, 0);
		this.setBlock(world, i + 3, j + 0, k + 6, Blocks.bedrock, 0);
		this.setBlock(world, i + 3, j + 0, k + 7, Blocks.bedrock, 0);
		this.setBlock(world, i + 3, j + 0, k + 8, Blocks.bedrock, 0);
		this.setBlock(world, i + 3, j + 0, k + 9, Blocks.bedrock, 0);
		this.setBlock(world, i + 3, j + 0, k + 10, Blocks.bedrock, 0);
		this.setBlock(world, i + 3, j + 1, k + 0, Blocks.bedrock, 0);
		this.setBlock(world, i + 3, j + 1, k + 1, Blocks.dirt, 0);
		this.setBlock(world, i + 3, j + 1, k + 2, Blocks.air, 0);
		this.setBlock(world, i + 3, j + 1, k + 3, Blocks.air, 0);
		this.setBlock(world, i + 3, j + 1, k + 4, Blocks.air, 0);
		this.setBlock(world, i + 3, j + 1, k + 5, Blocks.air, 0);
		this.setBlock(world, i + 3, j + 1, k + 6, Blocks.air, 0);
		this.setBlock(world, i + 3, j + 1, k + 7, Blocks.air, 0);
		this.setBlock(world, i + 3, j + 1, k + 8, Blocks.air, 0);
		this.setBlock(world, i + 3, j + 1, k + 9, Blocks.air, 0);
		this.setBlock(world, i + 3, j + 1, k + 10, Blocks.bedrock, 0);
		this.setBlock(world, i + 3, j + 2, k + 0, Blocks.bedrock, 0);
		this.setBlock(world, i + 3, j + 2, k + 1, Blocks.air, 0);
		this.setBlock(world, i + 3, j + 2, k + 2, Blocks.air, 0);
		this.setBlock(world, i + 3, j + 2, k + 3, Blocks.air, 0);
		this.setBlock(world, i + 3, j + 2, k + 4, Blocks.air, 0);
		this.setBlock(world, i + 3, j + 2, k + 5, Blocks.air, 0);
		this.setBlock(world, i + 3, j + 2, k + 6, Blocks.air, 0);
		this.setBlock(world, i + 3, j + 2, k + 7, Blocks.air, 0);
		this.setBlock(world, i + 3, j + 2, k + 8, Blocks.air, 0);
		this.setBlock(world, i + 3, j + 2, k + 9, Blocks.air, 0);
		this.setBlock(world, i + 3, j + 2, k + 10, Blocks.bedrock, 0);
		this.setBlock(world, i + 3, j + 3, k + 0, Blocks.bedrock, 0);
		this.setBlock(world, i + 3, j + 3, k + 1, Blocks.air, 0);
		this.setBlock(world, i + 3, j + 3, k + 2, Blocks.air, 0);
		this.setBlock(world, i + 3, j + 3, k + 3, Blocks.air, 0);
		this.setBlock(world, i + 3, j + 3, k + 4, Blocks.air, 0);
		this.setBlock(world, i + 3, j + 3, k + 5, Blocks.air, 0);
		this.setBlock(world, i + 3, j + 3, k + 6, Blocks.air, 0);
		this.setBlock(world, i + 3, j + 3, k + 7, Blocks.air, 0);
		this.setBlock(world, i + 3, j + 3, k + 8, Blocks.air, 0);
		this.setBlock(world, i + 3, j + 3, k + 9, Blocks.air, 0);
		this.setBlock(world, i + 3, j + 3, k + 10, Blocks.bedrock, 0);
		this.setBlock(world, i + 3, j + 4, k + 0, Blocks.bedrock, 0);
		this.setBlock(world, i + 3, j + 4, k + 1, Blocks.air, 0);
		this.setBlock(world, i + 3, j + 4, k + 2, Blocks.air, 0);
		this.setBlock(world, i + 3, j + 4, k + 3, Blocks.air, 0);
		this.setBlock(world, i + 3, j + 4, k + 4, Blocks.air, 0);
		this.setBlock(world, i + 3, j + 4, k + 5, Blocks.air, 0);
		this.setBlock(world, i + 3, j + 4, k + 6, Blocks.air, 0);
		this.setBlock(world, i + 3, j + 4, k + 7, Blocks.air, 0);
		this.setBlock(world, i + 3, j + 4, k + 8, Blocks.air, 0);
		this.setBlock(world, i + 3, j + 4, k + 9, Blocks.air, 0);
		this.setBlock(world, i + 3, j + 4, k + 10, Blocks.bedrock, 0);
		this.setBlock(world, i + 3, j + 5, k + 0, Blocks.bedrock, 0);
		this.setBlock(world, i + 3, j + 5, k + 1, Blocks.air, 0);
		this.setBlock(world, i + 3, j + 5, k + 2, Blocks.air, 0);
		this.setBlock(world, i + 3, j + 5, k + 3, Blocks.air, 0);
		this.setBlock(world, i + 3, j + 5, k + 4, Blocks.air, 0);
		this.setBlock(world, i + 3, j + 5, k + 5, Blocks.air, 0);
		this.setBlock(world, i + 3, j + 5, k + 6, Blocks.air, 0);
		this.setBlock(world, i + 3, j + 5, k + 7, Blocks.air, 0);
		this.setBlock(world, i + 3, j + 5, k + 8, Blocks.air, 0);
		this.setBlock(world, i + 3, j + 5, k + 9, Blocks.air, 0);
		this.setBlock(world, i + 3, j + 5, k + 10, Blocks.bedrock, 0);
		this.setBlock(world, i + 3, j + 6, k + 0, Blocks.bedrock, 0);
		this.setBlock(world, i + 3, j + 6, k + 1, Blocks.air, 0);
		this.setBlock(world, i + 3, j + 6, k + 2, Blocks.air, 0);
		this.setBlock(world, i + 3, j + 6, k + 3, Blocks.air, 0);
		this.setBlock(world, i + 3, j + 6, k + 4, Blocks.air, 0);
		this.setBlock(world, i + 3, j + 6, k + 5, Blocks.air, 0);
		this.setBlock(world, i + 3, j + 6, k + 6, Blocks.air, 0);
		this.setBlock(world, i + 3, j + 6, k + 7, Blocks.air, 0);
		this.setBlock(world, i + 3, j + 6, k + 8, Blocks.air, 0);
		this.setBlock(world, i + 3, j + 6, k + 9, Blocks.air, 0);
		this.setBlock(world, i + 3, j + 6, k + 10, Blocks.bedrock, 0);
		this.setBlock(world, i + 4, j + 0, k + 0, Blocks.bedrock, 0);
		this.setBlock(world, i + 4, j + 0, k + 1, Blocks.bedrock, 0);
		this.setBlock(world, i + 4, j + 0, k + 2, Blocks.bedrock, 0);
		this.setBlock(world, i + 4, j + 0, k + 3, Blocks.bedrock, 0);
		this.setBlock(world, i + 4, j + 0, k + 4, Blocks.bedrock, 0);
		this.setBlock(world, i + 4, j + 0, k + 5, Blocks.bedrock, 0);
		this.setBlock(world, i + 4, j + 0, k + 6, Blocks.bedrock, 0);
		this.setBlock(world, i + 4, j + 0, k + 7, Blocks.bedrock, 0);
		this.setBlock(world, i + 4, j + 0, k + 8, Blocks.bedrock, 0);
		this.setBlock(world, i + 4, j + 0, k + 9, Blocks.bedrock, 0);
		this.setBlock(world, i + 4, j + 0, k + 10, Blocks.bedrock, 0);
		this.setBlock(world, i + 4, j + 1, k + 0, Blocks.bedrock, 0);
		this.setBlock(world, i + 4, j + 1, k + 1, Blocks.air, 0);
		this.setBlock(world, i + 4, j + 1, k + 2, Blocks.air, 0);
		this.setBlock(world, i + 4, j + 1, k + 3, Blocks.air, 0);
		this.setBlock(world, i + 4, j + 1, k + 4, Blocks.air, 0);
		this.setBlock(world, i + 4, j + 1, k + 5, Blocks.air, 0);
		this.setBlock(world, i + 4, j + 1, k + 6, Blocks.air, 0);
		this.setBlock(world, i + 4, j + 1, k + 7, Blocks.air, 0);
		this.setBlock(world, i + 4, j + 1, k + 8, Blocks.air, 0);
		this.setBlock(world, i + 4, j + 1, k + 9, Blocks.air, 0);
		this.setBlock(world, i + 4, j + 1, k + 10, Blocks.bedrock, 0);
		this.setBlock(world, i + 4, j + 2, k + 0, Blocks.bedrock, 0);
		this.setBlock(world, i + 4, j + 2, k + 1, Blocks.air, 0);
		this.setBlock(world, i + 4, j + 2, k + 2, Blocks.air, 0);
		this.setBlock(world, i + 4, j + 2, k + 3, Blocks.air, 0);
		this.setBlock(world, i + 4, j + 2, k + 4, Blocks.air, 0);
		this.setBlock(world, i + 4, j + 2, k + 5, Blocks.air, 0);
		this.setBlock(world, i + 4, j + 2, k + 6, Blocks.air, 0);
		this.setBlock(world, i + 4, j + 2, k + 7, Blocks.air, 0);
		this.setBlock(world, i + 4, j + 2, k + 8, Blocks.air, 0);
		this.setBlock(world, i + 4, j + 2, k + 9, Blocks.air, 0);
		this.setBlock(world, i + 4, j + 2, k + 10, Blocks.bedrock, 0);
		this.setBlock(world, i + 4, j + 3, k + 0, Blocks.bedrock, 0);
		this.setBlock(world, i + 4, j + 3, k + 1, Blocks.air, 0);
		this.setBlock(world, i + 4, j + 3, k + 2, Blocks.air, 0);
		this.setBlock(world, i + 4, j + 3, k + 3, Blocks.air, 0);
		this.setBlock(world, i + 4, j + 3, k + 4, Blocks.air, 0);
		this.setBlock(world, i + 4, j + 3, k + 5, Blocks.air, 0);
		this.setBlock(world, i + 4, j + 3, k + 6, Blocks.air, 0);
		this.setBlock(world, i + 4, j + 3, k + 7, Blocks.air, 0);
		this.setBlock(world, i + 4, j + 3, k + 8, Blocks.air, 0);
		this.setBlock(world, i + 4, j + 3, k + 9, Blocks.air, 0);
		this.setBlock(world, i + 4, j + 3, k + 10, Blocks.bedrock, 0);
		this.setBlock(world, i + 4, j + 4, k + 0, Blocks.bedrock, 0);
		this.setBlock(world, i + 4, j + 4, k + 1, Blocks.air, 0);
		this.setBlock(world, i + 4, j + 4, k + 2, Blocks.air, 0);
		this.setBlock(world, i + 4, j + 4, k + 3, Blocks.air, 0);
		this.setBlock(world, i + 4, j + 4, k + 4, Blocks.air, 0);
		this.setBlock(world, i + 4, j + 4, k + 5, Blocks.air, 0);
		this.setBlock(world, i + 4, j + 4, k + 6, Blocks.air, 0);
		this.setBlock(world, i + 4, j + 4, k + 7, Blocks.air, 0);
		this.setBlock(world, i + 4, j + 4, k + 8, Blocks.air, 0);
		this.setBlock(world, i + 4, j + 4, k + 9, Blocks.air, 0);
		this.setBlock(world, i + 4, j + 4, k + 10, Blocks.bedrock, 0);
		this.setBlock(world, i + 4, j + 5, k + 0, Blocks.bedrock, 0);
		this.setBlock(world, i + 4, j + 5, k + 1, Blocks.air, 0);
		this.setBlock(world, i + 4, j + 5, k + 2, Blocks.air, 0);
		this.setBlock(world, i + 4, j + 5, k + 3, Blocks.air, 0);
		this.setBlock(world, i + 4, j + 5, k + 4, Blocks.air, 0);
		this.setBlock(world, i + 4, j + 5, k + 5, Blocks.air, 0);
		this.setBlock(world, i + 4, j + 5, k + 6, Blocks.air, 0);
		this.setBlock(world, i + 4, j + 5, k + 7, Blocks.air, 0);
		this.setBlock(world, i + 4, j + 5, k + 8, Blocks.air, 0);
		this.setBlock(world, i + 4, j + 5, k + 9, Blocks.air, 0);
		this.setBlock(world, i + 4, j + 5, k + 10, Blocks.bedrock, 0);
		this.setBlock(world, i + 4, j + 6, k + 0, Blocks.bedrock, 0);
		this.setBlock(world, i + 4, j + 6, k + 1, Blocks.air, 0);
		this.setBlock(world, i + 4, j + 6, k + 2, Blocks.air, 0);
		this.setBlock(world, i + 4, j + 6, k + 3, Blocks.air, 0);
		this.setBlock(world, i + 4, j + 6, k + 4, Blocks.air, 0);
		this.setBlock(world, i + 4, j + 6, k + 5, Blocks.air, 0);
		this.setBlock(world, i + 4, j + 6, k + 6, Blocks.air, 0);
		this.setBlock(world, i + 4, j + 6, k + 7, Blocks.air, 0);
		this.setBlock(world, i + 4, j + 6, k + 8, Blocks.air, 0);
		this.setBlock(world, i + 4, j + 6, k + 9, Blocks.air, 0);
		this.setBlock(world, i + 4, j + 6, k + 10, Blocks.bedrock, 0);
		this.setBlock(world, i + 5, j + 0, k + 0, Blocks.bedrock, 0);
		this.setBlock(world, i + 5, j + 0, k + 1, Blocks.bedrock, 0);
		this.setBlock(world, i + 5, j + 0, k + 2, Blocks.bedrock, 0);
		this.setBlock(world, i + 5, j + 0, k + 3, Blocks.bedrock, 0);
		this.setBlock(world, i + 5, j + 0, k + 4, Blocks.bedrock, 0);
		this.setBlock(world, i + 5, j + 0, k + 5, Blocks.bedrock, 0);
		this.setBlock(world, i + 5, j + 0, k + 6, Blocks.bedrock, 0);
		this.setBlock(world, i + 5, j + 0, k + 7, Blocks.bedrock, 0);
		this.setBlock(world, i + 5, j + 0, k + 8, Blocks.bedrock, 0);
		this.setBlock(world, i + 5, j + 0, k + 9, Blocks.bedrock, 0);
		this.setBlock(world, i + 5, j + 0, k + 10, Blocks.bedrock, 0);
		this.setBlock(world, i + 5, j + 1, k + 0, Blocks.bedrock, 0);
		this.setBlock(world, i + 5, j + 1, k + 1, Blocks.air, 0);
		this.setBlock(world, i + 5, j + 1, k + 2, Blocks.air, 0);
		this.setBlock(world, i + 5, j + 1, k + 3, Blocks.air, 0);
		this.setBlock(world, i + 5, j + 1, k + 4, Blocks.air, 0);
		this.setBlock(world, i + 5, j + 1, k + 5, Blocks.air, 0);
		this.setBlock(world, i + 5, j + 1, k + 6, Blocks.air, 0);
		this.setBlock(world, i + 5, j + 1, k + 7, Blocks.air, 0);
		this.setBlock(world, i + 5, j + 1, k + 8, Blocks.air, 0);
		this.setBlock(world, i + 5, j + 1, k + 9, Blocks.air, 0);
		this.setBlock(world, i + 5, j + 1, k + 10, Blocks.bedrock, 0);
		this.setBlock(world, i + 5, j + 2, k + 0, Blocks.bedrock, 0);
		this.setBlock(world, i + 5, j + 2, k + 1, Blocks.air, 0);
		this.setBlock(world, i + 5, j + 2, k + 2, Blocks.air, 0);
		this.setBlock(world, i + 5, j + 2, k + 3, Blocks.air, 0);
		this.setBlock(world, i + 5, j + 2, k + 4, Blocks.air, 0);
		this.setBlock(world, i + 5, j + 2, k + 5, Blocks.air, 0);
		this.setBlock(world, i + 5, j + 2, k + 6, Blocks.air, 0);
		this.setBlock(world, i + 5, j + 2, k + 7, Blocks.air, 0);
		this.setBlock(world, i + 5, j + 2, k + 8, Blocks.air, 0);
		this.setBlock(world, i + 5, j + 2, k + 9, Blocks.air, 0);
		this.setBlock(world, i + 5, j + 2, k + 10, Blocks.bedrock, 0);
		this.setBlock(world, i + 5, j + 3, k + 0, Blocks.bedrock, 0);
		this.setBlock(world, i + 5, j + 3, k + 1, Blocks.air, 0);
		this.setBlock(world, i + 5, j + 3, k + 2, Blocks.air, 0);
		this.setBlock(world, i + 5, j + 3, k + 3, Blocks.air, 0);
		this.setBlock(world, i + 5, j + 3, k + 4, Blocks.air, 0);
		this.setBlock(world, i + 5, j + 3, k + 5, Blocks.air, 0);
		this.setBlock(world, i + 5, j + 3, k + 6, Blocks.air, 0);
		this.setBlock(world, i + 5, j + 3, k + 7, Blocks.air, 0);
		this.setBlock(world, i + 5, j + 3, k + 8, Blocks.air, 0);
		this.setBlock(world, i + 5, j + 3, k + 9, Blocks.air, 0);
		this.setBlock(world, i + 5, j + 3, k + 10, Blocks.bedrock, 0);
		this.setBlock(world, i + 5, j + 4, k + 0, Blocks.bedrock, 0);
		this.setBlock(world, i + 5, j + 4, k + 1, Blocks.air, 0);
		this.setBlock(world, i + 5, j + 4, k + 2, Blocks.air, 0);
		this.setBlock(world, i + 5, j + 4, k + 3, Blocks.air, 0);
		this.setBlock(world, i + 5, j + 4, k + 4, Blocks.air, 0);
		this.setBlock(world, i + 5, j + 4, k + 5, Blocks.air, 0);
		this.setBlock(world, i + 5, j + 4, k + 6, Blocks.air, 0);
		this.setBlock(world, i + 5, j + 4, k + 7, Blocks.air, 0);
		this.setBlock(world, i + 5, j + 4, k + 8, Blocks.air, 0);
		this.setBlock(world, i + 5, j + 4, k + 9, Blocks.air, 0);
		this.setBlock(world, i + 5, j + 4, k + 10, Blocks.bedrock, 0);
		this.setBlock(world, i + 5, j + 5, k + 0, Blocks.bedrock, 0);
		this.setBlock(world, i + 5, j + 5, k + 1, Blocks.air, 0);
		this.setBlock(world, i + 5, j + 5, k + 2, Blocks.air, 0);
		this.setBlock(world, i + 5, j + 5, k + 3, Blocks.air, 0);
		this.setBlock(world, i + 5, j + 5, k + 4, Blocks.air, 0);
		this.setBlock(world, i + 5, j + 5, k + 5, Blocks.air, 0);
		this.setBlock(world, i + 5, j + 5, k + 6, Blocks.air, 0);
		this.setBlock(world, i + 5, j + 5, k + 7, Blocks.air, 0);
		this.setBlock(world, i + 5, j + 5, k + 8, Blocks.air, 0);
		this.setBlock(world, i + 5, j + 5, k + 9, Blocks.air, 0);
		this.setBlock(world, i + 5, j + 5, k + 10, Blocks.bedrock, 0);
		this.setBlock(world, i + 5, j + 6, k + 0, Blocks.bedrock, 0);
		this.setBlock(world, i + 5, j + 6, k + 1, Blocks.air, 0);
		this.setBlock(world, i + 5, j + 6, k + 2, Blocks.air, 0);
		this.setBlock(world, i + 5, j + 6, k + 3, Blocks.air, 0);
		this.setBlock(world, i + 5, j + 6, k + 4, Blocks.air, 0);
		this.setBlock(world, i + 5, j + 6, k + 5, Blocks.air, 0);
		this.setBlock(world, i + 5, j + 6, k + 6, Blocks.air, 0);
		this.setBlock(world, i + 5, j + 6, k + 7, Blocks.air, 0);
		this.setBlock(world, i + 5, j + 6, k + 8, Blocks.air, 0);
		this.setBlock(world, i + 5, j + 6, k + 9, Blocks.air, 0);
		this.setBlock(world, i + 5, j + 6, k + 10, Blocks.bedrock, 0);
		this.setBlock(world, i + 6, j + 0, k + 0, Blocks.bedrock, 0);
		this.setBlock(world, i + 6, j + 0, k + 1, Blocks.bedrock, 0);
		this.setBlock(world, i + 6, j + 0, k + 2, Blocks.bedrock, 0);
		this.setBlock(world, i + 6, j + 0, k + 3, Blocks.bedrock, 0);
		this.setBlock(world, i + 6, j + 0, k + 4, Blocks.bedrock, 0);
		this.setBlock(world, i + 6, j + 0, k + 5, Blocks.bedrock, 0);
		this.setBlock(world, i + 6, j + 0, k + 6, Blocks.bedrock, 0);
		this.setBlock(world, i + 6, j + 0, k + 7, Blocks.bedrock, 0);
		this.setBlock(world, i + 6, j + 0, k + 8, Blocks.bedrock, 0);
		this.setBlock(world, i + 6, j + 0, k + 9, Blocks.bedrock, 0);
		this.setBlock(world, i + 6, j + 0, k + 10, Blocks.bedrock, 0);
		this.setBlock(world, i + 6, j + 1, k + 0, Blocks.bedrock, 0);
		this.setBlock(world, i + 6, j + 1, k + 1, Blocks.air, 0);
		this.setBlock(world, i + 6, j + 1, k + 2, Blocks.air, 0);
		this.setBlock(world, i + 6, j + 1, k + 3, Blocks.air, 0);
		this.setBlock(world, i + 6, j + 1, k + 4, Blocks.dirt, 0);
		this.setBlock(world, i + 6, j + 1, k + 5, Blocks.air, 0);
		this.setBlock(world, i + 6, j + 1, k + 6, Blocks.air, 0);
		this.setBlock(world, i + 6, j + 1, k + 7, Blocks.air, 0);
		this.setBlock(world, i + 6, j + 1, k + 8, Blocks.air, 0);
		this.setBlock(world, i + 6, j + 1, k + 9, Blocks.air, 0);
		this.setBlock(world, i + 6, j + 1, k + 10, Blocks.bedrock, 0);
		this.setBlock(world, i + 6, j + 2, k + 0, Blocks.bedrock, 0);
		this.setBlock(world, i + 6, j + 2, k + 1, Blocks.air, 0);
		this.setBlock(world, i + 6, j + 2, k + 2, Blocks.air, 0);
		this.setBlock(world, i + 6, j + 2, k + 3, Blocks.air, 0);
		this.setBlock(world, i + 6, j + 2, k + 4, Blocks.dirt, 0);
		this.setBlock(world, i + 6, j + 2, k + 5, Blocks.air, 0);
		this.setBlock(world, i + 6, j + 2, k + 6, Blocks.air, 0);
		this.setBlock(world, i + 6, j + 2, k + 7, Blocks.air, 0);
		this.setBlock(world, i + 6, j + 2, k + 8, Blocks.air, 0);
		this.setBlock(world, i + 6, j + 2, k + 9, Blocks.air, 0);
		this.setBlock(world, i + 6, j + 2, k + 10, Blocks.bedrock, 0);
		this.setBlock(world, i + 6, j + 3, k + 0, Blocks.bedrock, 0);
		this.setBlock(world, i + 6, j + 3, k + 1, Blocks.air, 0);
		this.setBlock(world, i + 6, j + 3, k + 2, Blocks.air, 0);
		this.setBlock(world, i + 6, j + 3, k + 3, Blocks.air, 0);
		this.setBlock(world, i + 6, j + 3, k + 4, Blocks.air, 0);
		this.setBlock(world, i + 6, j + 3, k + 5, Blocks.air, 0);
		this.setBlock(world, i + 6, j + 3, k + 6, Blocks.air, 0);
		this.setBlock(world, i + 6, j + 3, k + 7, Blocks.air, 0);
		this.setBlock(world, i + 6, j + 3, k + 8, Blocks.air, 0);
		this.setBlock(world, i + 6, j + 3, k + 9, Blocks.air, 0);
		this.setBlock(world, i + 6, j + 3, k + 10, Blocks.bedrock, 0);
		this.setBlock(world, i + 6, j + 4, k + 0, Blocks.bedrock, 0);
		this.setBlock(world, i + 6, j + 4, k + 1, Blocks.air, 0);
		this.setBlock(world, i + 6, j + 4, k + 2, Blocks.air, 0);
		this.setBlock(world, i + 6, j + 4, k + 3, Blocks.air, 0);
		this.setBlock(world, i + 6, j + 4, k + 4, Blocks.air, 0);
		this.setBlock(world, i + 6, j + 4, k + 5, Blocks.air, 0);
		this.setBlock(world, i + 6, j + 4, k + 6, Blocks.air, 0);
		this.setBlock(world, i + 6, j + 4, k + 7, Blocks.air, 0);
		this.setBlock(world, i + 6, j + 4, k + 8, Blocks.air, 0);
		this.setBlock(world, i + 6, j + 4, k + 9, Blocks.air, 0);
		this.setBlock(world, i + 6, j + 4, k + 10, Blocks.bedrock, 0);
		this.setBlock(world, i + 6, j + 5, k + 0, Blocks.bedrock, 0);
		this.setBlock(world, i + 6, j + 5, k + 1, Blocks.air, 0);
		this.setBlock(world, i + 6, j + 5, k + 2, Blocks.air, 0);
		this.setBlock(world, i + 6, j + 5, k + 3, Blocks.air, 0);
		this.setBlock(world, i + 6, j + 5, k + 4, Blocks.air, 0);
		this.setBlock(world, i + 6, j + 5, k + 5, Blocks.air, 0);
		this.setBlock(world, i + 6, j + 5, k + 6, Blocks.air, 0);
		this.setBlock(world, i + 6, j + 5, k + 7, Blocks.air, 0);
		this.setBlock(world, i + 6, j + 5, k + 8, Blocks.air, 0);
		this.setBlock(world, i + 6, j + 5, k + 9, Blocks.air, 0);
		this.setBlock(world, i + 6, j + 5, k + 10, Blocks.bedrock, 0);
		this.setBlock(world, i + 6, j + 6, k + 0, Blocks.bedrock, 0);
		this.setBlock(world, i + 6, j + 6, k + 1, Blocks.air, 0);
		this.setBlock(world, i + 6, j + 6, k + 2, Blocks.air, 0);
		this.setBlock(world, i + 6, j + 6, k + 3, Blocks.air, 0);
		this.setBlock(world, i + 6, j + 6, k + 4, Blocks.air, 0);
		this.setBlock(world, i + 6, j + 6, k + 5, Blocks.air, 0);
		this.setBlock(world, i + 6, j + 6, k + 6, Blocks.air, 0);
		this.setBlock(world, i + 6, j + 6, k + 7, Blocks.air, 0);
		this.setBlock(world, i + 6, j + 6, k + 8, Blocks.air, 0);
		this.setBlock(world, i + 6, j + 6, k + 9, Blocks.air, 0);
		this.setBlock(world, i + 6, j + 6, k + 10, Blocks.bedrock, 0);
		this.setBlock(world, i + 7, j + 0, k + 0, Blocks.bedrock, 0);
		this.setBlock(world, i + 7, j + 0, k + 1, Blocks.bedrock, 0);
		this.setBlock(world, i + 7, j + 0, k + 2, Blocks.bedrock, 0);
		this.setBlock(world, i + 7, j + 0, k + 3, Blocks.bedrock, 0);
		this.setBlock(world, i + 7, j + 0, k + 4, Blocks.bedrock, 0);
		this.setBlock(world, i + 7, j + 0, k + 5, Blocks.bedrock, 0);
		this.setBlock(world, i + 7, j + 0, k + 6, Blocks.bedrock, 0);
		this.setBlock(world, i + 7, j + 0, k + 7, Blocks.bedrock, 0);
		this.setBlock(world, i + 7, j + 0, k + 8, Blocks.bedrock, 0);
		this.setBlock(world, i + 7, j + 0, k + 9, Blocks.bedrock, 0);
		this.setBlock(world, i + 7, j + 0, k + 10, Blocks.bedrock, 0);
		this.setBlock(world, i + 7, j + 1, k + 0, Blocks.bedrock, 0);
		this.setBlock(world, i + 7, j + 1, k + 1, Blocks.bedrock, 0);
		this.setBlock(world, i + 7, j + 1, k + 2, Blocks.bedrock, 0);
		this.setBlock(world, i + 7, j + 1, k + 3, Blocks.bedrock, 0);
		this.setBlock(world, i + 7, j + 1, k + 4, Blocks.bedrock, 0);
		this.setBlock(world, i + 7, j + 1, k + 5, Blocks.bedrock, 0);
		this.setBlock(world, i + 7, j + 1, k + 6, Blocks.bedrock, 0);
		this.setBlock(world, i + 7, j + 1, k + 7, Blocks.bedrock, 0);
		this.setBlock(world, i + 7, j + 1, k + 8, Blocks.bedrock, 0);
		this.setBlock(world, i + 7, j + 1, k + 9, Blocks.bedrock, 0);
		this.setBlock(world, i + 7, j + 1, k + 10, Blocks.bedrock, 0);
		this.setBlock(world, i + 7, j + 2, k + 0, Blocks.bedrock, 0);
		this.setBlock(world, i + 7, j + 2, k + 1, Blocks.bedrock, 0);
		this.setBlock(world, i + 7, j + 2, k + 2, Blocks.bedrock, 0);
		this.setBlock(world, i + 7, j + 2, k + 3, Blocks.bedrock, 0);
		this.setBlock(world, i + 7, j + 2, k + 4, Blocks.bedrock, 0);
		this.setBlock(world, i + 7, j + 2, k + 5, Blocks.bedrock, 0);
		this.setBlock(world, i + 7, j + 2, k + 6, Blocks.bedrock, 0);
		this.setBlock(world, i + 7, j + 2, k + 7, Blocks.bedrock, 0);
		this.setBlock(world, i + 7, j + 2, k + 8, Blocks.bedrock, 0);
		this.setBlock(world, i + 7, j + 2, k + 9, Blocks.bedrock, 0);
		this.setBlock(world, i + 7, j + 2, k + 10, Blocks.bedrock, 0);
		this.setBlock(world, i + 7, j + 3, k + 0, Blocks.bedrock, 0);
		this.setBlock(world, i + 7, j + 3, k + 1, Blocks.bedrock, 0);
		this.setBlock(world, i + 7, j + 3, k + 2, Blocks.bedrock, 0);
		this.setBlock(world, i + 7, j + 3, k + 3, Blocks.bedrock, 0);
		this.setBlock(world, i + 7, j + 3, k + 4, Blocks.bedrock, 0);
		this.setBlock(world, i + 7, j + 3, k + 5, Blocks.bedrock, 0);
		this.setBlock(world, i + 7, j + 3, k + 6, Blocks.bedrock, 0);
		this.setBlock(world, i + 7, j + 3, k + 7, Blocks.bedrock, 0);
		this.setBlock(world, i + 7, j + 3, k + 8, Blocks.bedrock, 0);
		this.setBlock(world, i + 7, j + 3, k + 9, Blocks.bedrock, 0);
		this.setBlock(world, i + 7, j + 3, k + 10, Blocks.bedrock, 0);
		this.setBlock(world, i + 7, j + 4, k + 0, Blocks.bedrock, 0);
		this.setBlock(world, i + 7, j + 4, k + 1, Blocks.bedrock, 0);
		this.setBlock(world, i + 7, j + 4, k + 2, Blocks.bedrock, 0);
		this.setBlock(world, i + 7, j + 4, k + 3, Blocks.bedrock, 0);
		this.setBlock(world, i + 7, j + 4, k + 4, Blocks.bedrock, 0);
		this.setBlock(world, i + 7, j + 4, k + 5, Blocks.bedrock, 0);
		this.setBlock(world, i + 7, j + 4, k + 6, Blocks.bedrock, 0);
		this.setBlock(world, i + 7, j + 4, k + 7, Blocks.bedrock, 0);
		this.setBlock(world, i + 7, j + 4, k + 8, Blocks.bedrock, 0);
		this.setBlock(world, i + 7, j + 4, k + 9, Blocks.bedrock, 0);
		this.setBlock(world, i + 7, j + 4, k + 10, Blocks.bedrock, 0);
		this.setBlock(world, i + 7, j + 5, k + 0, Blocks.bedrock, 0);
		this.setBlock(world, i + 7, j + 5, k + 1, Blocks.bedrock, 0);
		this.setBlock(world, i + 7, j + 5, k + 2, Blocks.bedrock, 0);
		this.setBlock(world, i + 7, j + 5, k + 3, Blocks.bedrock, 0);
		this.setBlock(world, i + 7, j + 5, k + 4, Blocks.bedrock, 0);
		this.setBlock(world, i + 7, j + 5, k + 5, Blocks.bedrock, 0);
		this.setBlock(world, i + 7, j + 5, k + 6, Blocks.bedrock, 0);
		this.setBlock(world, i + 7, j + 5, k + 7, Blocks.bedrock, 0);
		this.setBlock(world, i + 7, j + 5, k + 8, Blocks.bedrock, 0);
		this.setBlock(world, i + 7, j + 5, k + 9, Blocks.bedrock, 0);
		this.setBlock(world, i + 7, j + 5, k + 10, Blocks.bedrock, 0);
		this.setBlock(world, i + 7, j + 6, k + 0, Blocks.bedrock, 0);
		this.setBlock(world, i + 7, j + 6, k + 1, Blocks.bedrock, 0);
		this.setBlock(world, i + 7, j + 6, k + 2, Blocks.bedrock, 0);
		this.setBlock(world, i + 7, j + 6, k + 3, Blocks.bedrock, 0);
		this.setBlock(world, i + 7, j + 6, k + 4, Blocks.bedrock, 0);
		this.setBlock(world, i + 7, j + 6, k + 5, Blocks.bedrock, 0);
		this.setBlock(world, i + 7, j + 6, k + 6, Blocks.bedrock, 0);
		this.setBlock(world, i + 7, j + 6, k + 7, Blocks.bedrock, 0);
		this.setBlock(world, i + 7, j + 6, k + 8, Blocks.bedrock, 0);
		this.setBlock(world, i + 7, j + 6, k + 9, Blocks.bedrock, 0);
		this.setBlock(world, i + 7, j + 6, k + 10, Blocks.bedrock, 0);

		return true;
	}
}