package edu.brown.cs.h2r.burlapcraft.dungeongenerator;

import java.util.Random;

import net.minecraft.block.Block;
import net.minecraft.world.World;
import net.minecraft.world.gen.feature.WorldGenerator;

public class DungeonGeneratorGrid extends WorldGenerator {

	@Override
	public boolean generate(World world, Random rand, int x, int y, int z) {
		System.out.println("Making dungeon at " + x + "," + y + "," + z);
		world.setBlock(x+0, y+0, z+0, Block.getBlockById(7));
		world.setBlock(x+1, y+0, z+0, Block.getBlockById(7));
		world.setBlock(x+2, y+0, z+0, Block.getBlockById(7));
		world.setBlock(x+3, y+0, z+0, Block.getBlockById(7));
		world.setBlock(x+4, y+0, z+0, Block.getBlockById(7));
		world.setBlock(x+0, y+0, z+1, Block.getBlockById(7));
		world.setBlock(x+1, y+0, z+1, Block.getBlockById(41));
		world.setBlock(x+2, y+0, z+1, Block.getBlockById(7));
		world.setBlock(x+3, y+0, z+1, Block.getBlockById(7));
		world.setBlock(x+4, y+0, z+1, Block.getBlockById(7));
		world.setBlock(x+0, y+0, z+2, Block.getBlockById(7));
		world.setBlock(x+1, y+0, z+2, Block.getBlockById(7));
		world.setBlock(x+2, y+0, z+2, Block.getBlockById(7));
		world.setBlock(x+3, y+0, z+2, Block.getBlockById(7));
		world.setBlock(x+4, y+0, z+2, Block.getBlockById(7));
		world.setBlock(x+0, y+0, z+3, Block.getBlockById(7));
		world.setBlock(x+1, y+0, z+3, Block.getBlockById(7));
		world.setBlock(x+2, y+0, z+3, Block.getBlockById(7));
		world.setBlock(x+3, y+0, z+3, Block.getBlockById(7));
		world.setBlock(x+4, y+0, z+3, Block.getBlockById(7));
		world.setBlock(x+0, y+0, z+4, Block.getBlockById(7));
		world.setBlock(x+1, y+0, z+4, Block.getBlockById(7));
		world.setBlock(x+2, y+0, z+4, Block.getBlockById(7));
		world.setBlock(x+3, y+0, z+4, Block.getBlockById(7));
		world.setBlock(x+4, y+0, z+4, Block.getBlockById(7));
		world.setBlock(x+0, y+1, z+0, Block.getBlockById(7));
		world.setBlock(x+1, y+1, z+0, Block.getBlockById(7));
		world.setBlock(x+2, y+1, z+0, Block.getBlockById(7));
		world.setBlock(x+3, y+1, z+0, Block.getBlockById(7));
		world.setBlock(x+4, y+1, z+0, Block.getBlockById(7));
		world.setBlock(x+0, y+1, z+1, Block.getBlockById(7));
		world.setBlock(x+1, y+1, z+1, Block.getBlockById(0));
		world.setBlock(x+2, y+1, z+1, Block.getBlockById(0));
		world.setBlock(x+3, y+1, z+1, Block.getBlockById(0));
		world.setBlock(x+4, y+1, z+1, Block.getBlockById(7));
		world.setBlock(x+0, y+1, z+2, Block.getBlockById(7));
		world.setBlock(x+1, y+1, z+2, Block.getBlockById(7));
		world.setBlock(x+2, y+1, z+2, Block.getBlockById(0));
		world.setBlock(x+3, y+1, z+2, Block.getBlockById(0));
		world.setBlock(x+4, y+1, z+2, Block.getBlockById(7));
		world.setBlock(x+0, y+1, z+3, Block.getBlockById(7));
		world.setBlock(x+1, y+1, z+3, Block.getBlockById(0));
		world.setBlock(x+2, y+1, z+3, Block.getBlockById(0));
		world.setBlock(x+3, y+1, z+3, Block.getBlockById(0));
		world.setBlock(x+4, y+1, z+3, Block.getBlockById(7));
		world.setBlock(x+0, y+1, z+4, Block.getBlockById(7));
		world.setBlock(x+1, y+1, z+4, Block.getBlockById(7));
		world.setBlock(x+2, y+1, z+4, Block.getBlockById(7));
		world.setBlock(x+3, y+1, z+4, Block.getBlockById(7));
		world.setBlock(x+4, y+1, z+4, Block.getBlockById(7));
		world.setBlock(x+0, y+2, z+0, Block.getBlockById(7));
		world.setBlock(x+1, y+2, z+0, Block.getBlockById(7));
		world.setBlock(x+2, y+2, z+0, Block.getBlockById(7));
		world.setBlock(x+3, y+2, z+0, Block.getBlockById(7));
		world.setBlock(x+4, y+2, z+0, Block.getBlockById(7));
		world.setBlock(x+0, y+2, z+1, Block.getBlockById(7));
		world.setBlock(x+1, y+2, z+1, Block.getBlockById(0));
		world.setBlock(x+2, y+2, z+1, Block.getBlockById(0));
		world.setBlock(x+3, y+2, z+1, Block.getBlockById(0));
		world.setBlock(x+4, y+2, z+1, Block.getBlockById(7));
		world.setBlock(x+0, y+2, z+2, Block.getBlockById(7));
		world.setBlock(x+1, y+2, z+2, Block.getBlockById(7));
		world.setBlock(x+2, y+2, z+2, Block.getBlockById(0));
		world.setBlock(x+3, y+2, z+2, Block.getBlockById(0));
		world.setBlock(x+4, y+2, z+2, Block.getBlockById(7));
		world.setBlock(x+0, y+2, z+3, Block.getBlockById(7));
		world.setBlock(x+1, y+2, z+3, Block.getBlockById(0));
		world.setBlock(x+2, y+2, z+3, Block.getBlockById(0));
		world.setBlock(x+3, y+2, z+3, Block.getBlockById(0));
		world.setBlock(x+4, y+2, z+3, Block.getBlockById(7));
		world.setBlock(x+0, y+2, z+4, Block.getBlockById(7));
		world.setBlock(x+1, y+2, z+4, Block.getBlockById(7));
		world.setBlock(x+2, y+2, z+4, Block.getBlockById(7));
		world.setBlock(x+3, y+2, z+4, Block.getBlockById(7));
		world.setBlock(x+4, y+2, z+4, Block.getBlockById(7));
		
		return true;
	}

}
